Workbook

Sheet 冷延条件
A1: 冷延条件_key** | B1: 入側板厚[mm] | C1: 出側板厚[mm] | D1: 冷延率[%] | E1: プロジェクト名 | F1: 登録者 | G1: 登録日
A2: CR-00001 | B2: 3.355 | C2: 1.201 | D2: 35.797317 | E2: 成形性改善PJ | F2: 高橋 | G2: 45542
A3: CR-00002 | B3: 3.469 | C3: 1.343 | D3: 38.714327 | E3: 表面品質PJ | F3: 山田 | G3: 45545
A4: CR-00003 | B4: 3.884 | C4: 1.465 | D4: 37.718847 | E4: 工程短縮PJ | F4: 高橋 | G4: 45548
A5: CR-00004 | B5: 3.426 | C5: 1.251 | D5: 36.514886 | E5: 薄板高強度化PJ | F5: 山田 | G5: 45551
A6: CR-00005 | B6: 3.211 | C6: 1.248 | D6: 38.866397 | E6: 工程短縮PJ | F6: 高橋 | G6: 45560
A7: CR-00006 | B7: 3.343 | C7: 1.34 | D7: 40.083757 | E7: 薄板高強度化PJ | F7: 山田 | G7: 45563
A8: CR-00007 | B8: 3.668 | C8: 1.402 | D8: 38.222465 | E8: 工程短縮PJ | F8: 高橋 | G8: 45572
A9: CR-00008 | B9: 3.668 | C9: 1.674 | D9: 45.63795 | E9: 工程短縮PJ | F9: 高橋 | G9: 45572
A10: CR-00009 | B10: 3.196 | C10: 1.156 | D10: 36.170213 | E10: 成形性改善PJ | F10: 高橋 | G10: 45578
A11: CR-00010 | B11: 3.887 | C11: 1.587 | D11: 40.828402 | E11: 表面品質PJ | F11: 山田 | G11: 45581
A12: CR-00011 | B12: 3.552 | C12: 1.464 | D12: 41.216216 | E12: 工程短縮PJ | F12: 高橋 | G12: 45584
A13: CR-00012 | B13: 3.83 | C13: 1.466 | D13: 38.276762 | E13: 表面品質PJ | F13: 山田 | G13: 45593
... A179: CR-00178 | B179: 2.1 | C179: 0.9 | D179: 42.857143 | E179: 工程短縮PJ | F179: 伊藤 | G179: 45839

Sheet relationEx
A1: 溶製成績書_key** | B1: 熱延条件_key** | C1: 冷延条件_key** | D1: 焼鈍履歴_key** | E1: 熱延引張実績_key** | F1: 熱延組織_key** | G1: 焼鈍引張実績_key** | H1: 焼鈍穴拡げ実績_key** | I1: 焼鈍板組織_key** | J1: dummy_key**
A2: ME-00001 | B2: HR-00001 | E2: HT-00001 | J2: dummy001
A3: ME-00001 | B3: HR-00001 | E3: HT-00002 | J3: dummy002
A4: ME-00001 | B4: HR-00001 | F4: HMS-00001 | J4: dummy003
A5: ME-00001 | B5: HR-00002 | E5: HT-00003 | J5: dummy004
A6: ME-00001 | B6: HR-00002 | F6: HMS-00002 | J6: dummy005
A7: ME-00001 | B7: HR-00002 | F7: HMS-00003 | J7: dummy006
A8: ME-00001 | B8: HR-00002 | F8: HMS-00004 | J8: dummy007
A9: ME-00002 | B9: HR-00003 | E9: HT-00004 | J9: dummy008
A10: ME-00002 | B10: HR-00003 | E10: HT-00005 | J10: dummy009
A11: ME-00002 | B11: HR-00003 | F11: HMS-00005 | J11: dummy010
A12: ME-00002 | B12: HR-00003 | F12: HMS-00006 | J12: dummy011
A13: ME-00002 | B13: HR-00003 | F13: HMS-00007 | J13: dummy012
A14: ME-00002 | B14: HR-00003 | F14: HMS-00008 | J14: dummy013
A15: ME-00003 | B15: HR-00004 | E15: HT-00006 | J15: dummy014
A16: ME-00003 | B16: HR-00004 | E16: HT-00007 | J16: dummy015
A17: ME-00003 | B17: HR-00005 | E17: HT-00008 | J17: dummy016
A18: ME-00003 | B18: HR-00005 | E18: HT-00009 | J18: dummy017
A19: ME-00003 | B19: HR-00005 | E19: HT-00010 | J19: dummy018
A20: ME-00004 | B20: HR-00006 | E20: HT-00011 | J20: dummy019
A21: ME-00004 | B21: HR-00007 | E21: HT-00012 | J21: dummy020
A22: ME-00004 | B22: HR-00007 | E22: HT-00013 | J22: dummy021
A23: ME-00005 | B23: HR-00008 | E23: HT-00014 | J23: dummy022
A24: ME-00005 | B24: HR-00008 | E24: HT-00015 | J24: dummy023
A25: ME-00005 | B25: HR-00008 | F25: HMS-00009 | J25: dummy024
A26: ME-00005 | B26: HR-00008 | F26: HMS-00010 | J26: dummy025
A27: ME-00005 | B27: HR-00009 | E27: HT-00016 | J27: dummy026
A28: ME-00005 | B28: HR-00009 | E28: HT-00017 | J28: dummy027
A29: ME-00005 | B29: HR-00009 | E29: HT-00018 | J29: dummy028
A30: ME-00006 | B30: HR-00010 | E30: HT-00019 | J30: dummy029
A31: ME-00006 | B31: HR-00010 | E31: HT-00020 | J31: dummy030
A32: ME-00006 | B32: HR-00010 | E32: HT-00021 | J32: dummy031
A33: ME-00006 | B33: HR-00010 | F33: HMS-00011 | J33: dummy032
A34: ME-00006 | B34: HR-00010 | F34: HMS-00012 | J34: dummy033
A35: ME-00007 | B35: HR-00011 | E35: HT-00022 | J35: dummy034
A36: ME-00007 | B36: HR-00011 | E36: HT-00023 | J36: dummy035
A37: ME-00007 | B37: HR-00011 | F37: HMS-00013 | J37: dummy036
A38: ME-00007 | B38: HR-00011 | F38: HMS-00014 | J38: dummy037
A39: ME-00007 | B39: HR-00011 | F39: HMS-00015 | J39: dummy038
A40: ME-00008 | B40: HR-00012 | E40: HT-00024 | J40: dummy039
...

Sheet 溶製成績書
A1: 溶製成績書_key** | B1: 管理番号 | C1: C[%] | D1: Si[%] | E1: Mn[%] | F1: P[%] | G1: S[%] | H1: Al[%] | I1: Cu[%] | J1: Ni[%] | K1: Cr[%] | L1: Mo[%] | M1: Ti[%] | N1: B[%] | O1: O[%] | P1: N[%] | Q1: ロット | R1: プロジェクト名 | S1: 登録者 | T1: 登録日
A2: ME-00001 | B2: CH-2024-0001 | C2: 0.04232 | D2: 0.1678 | E2: 0.80214 | F2: 0.00973 | G2: 0.0059 | H2: 0.03804 | I2: 0 | J2: 0.07294 | K2: 0.01699 | L2: 0 | M2: 0.00592 | N2: 0.0003 | O2: 0.00256 | P2: 0.00443 | Q2: ML-001 | R2: 薄板高強度化PJ | S2: 山田 | T2: 45299
A3: ME-00002 | B3: CH-2024-0002 | C3: 0.0691 | D3: 0.26634 | E3: 1.24391 | F3: 0.01339 | G3: 0.00524 | H3: 0.04931 | I3: 0 | J3: 0.10176 | K3: 0.06096 | L3: 0.04571 | M3: 0.03283 | N3: 0.00027 | O3: 0.00181 | P3: 0.0044 | Q3: ML-001 | R3: 成形性改善PJ | S3: 高橋 | T3: 45302
A4: ME-00003 | B4: CH-2024-0003 | C4: 0.0972 | D4: 0.41862 | E4: 1.78427 | F4: 0.01457 | G4: 0.00369 | H4: 0.02791 | I4: 0 | J4: 0.13964 | K4: 0.34556 | L4: 0.08071 | M4: 0.01435 | N4: 0.00117 | O4: 0.00277 | P4: 0.00638 | Q4: ML-001 | R4: 表面品質PJ | S4: 山田 | T4: 45305
A5: ME-00004 | B5: CH-2024-0004 | C5: 0.11148 | D5: 0.59856 | E5: 1.99112 | F5: 0.01642 | G5: 0.00273 | H5: 0.01335 | I5: 0 | J5: 0.15798 | K5: 0.52731 | L5: 0.18218 | M5: 0.01711 | N5: 0.0021 | O5: 0.0014 | P5: 0.00745 | Q5: ML-001 | R5: 工程短縮PJ | S5: 高橋 | T5: 45308
A6: ME-00005 | B6: CH-2024-0005 | C6: 0.03905 | D6: 0.14701 | E6: 0.79965 | F6: 0.00953 | G6: 0.00651 | H6: 0.0372 | I6: 0 | J6: 0.05528 | K6: 0.0219 | L6: 0.00843 | M6: 0.00828 | N6: 0 | O6: 0.00212 | P6: 0.00398 | Q6: ML-001 | R6: 薄板高強度化PJ | S6: 山田 | T6: 45311
A7: ME-00006 | B7: CH-2024-0006 | C7: 0.05831 | D7: 0.30264 | E7: 1.15097 | F7: 0.01251 | G7: 0.00341 | H7: 0.03576 | I7: 0 | J7: 0.08367 | K7: 0.11838 | L7: 0.03473 | M7: 0.02668 | N7: 0.00055 | O7: 0.00307 | P7: 0.00504 | Q7: ML-002 | R7: 成形性改善PJ | S7: 高橋 | T7: 45314
A8: ME-00007 | B8: CH-2024-0007 | C8: 0.10235 | D8: 0.44166 | E8: 1.75948 | F8: 0.01529 | G8: 0.00411 | H8: 0.02798 | I8: 0 | J8: 0.08808 | K8: 0.3558 | L8: 0.09025 | M8: 0.01116 | N8: 0.00126 | O8: 0.00194 | P8: 0.00625 | Q8: ML-002 | R8: 表面品質PJ | S8: 山田 | T8: 45317
A9: ME-00008 | B9: CH-2024-0008 | C9: 3.2 | D9: 0.65408 | E9: 1.94125 | F9: 0.0162 | G9: 0.00478 | H9: 0.01439 | I9: 0 | J9: 0.16146 | K9: 0.56978 | L9: 0.16827 | M9: 0.03084 | N9: 0.00168 | O9: 0.00232 | P9: 0.00677 | Q9: ML-002 | R9: 工程短縮PJ | S9: 高橋 | T9: 45320
A10: ME-00009 | B10: CH-2024-0009 | C10: 0.0318 | D10: 0.15336 | E10: 0.75204 | F10: 0.00924 | G10: 0.00619 | H10: 0.04092 | I10: 0 | J10: 0.0427 | K10: 0.05968 | L10: 0.01029 | M10: 0.00378 | N10: 0.0002 | O10: 0.00277 | P10: 0.00391 | Q10: ML-002 | R10: 薄板高強度化PJ | S10: 山田 | T10: 45323
A11: ME-00010 | B11: CH-2024-0010 | C11: 0.05988 | D11: 0.28619 | E11: 1.27646 | F11: 0.01186 | G11: 0.00398 | H11: 0.03957 | I11: 0 | J11: 0.0513 | K11: 0.07081 | L11: 0.0193 | M11: 0.03612 | N11: 0.00048 | O11: 0.00255 | P11: 0.0043 | Q11: ML-002 | R11: 成形性改善PJ | S11: 高橋 | T11: 45326
A12: ME-00011 | B12: CH-2024-0011 | C12: 0.10743 | D12: 0.43807 | E12: 1.8066 | F12: 0.01375 | G12: 0.00389 | H12: 0.02645 | I12: 0 | J12: 0.10051 | K12: 0.32678 | L12: 0.12933 | M12: 0.0104 | N12: 0.00187 | O12: 0.00193 | P12: 0.00472 | Q12: ML-003 | R12: 表面品質PJ | S12: 山田 | T12: 45329
A13: ME-00012 | B13: CH-2024-0012 | C13: 0.13799 | D13: 0.51995 | E13: 2.08688 | F13: 0.01724 | G13: 0.00269 | H13: 0.02699 | I13: 0 | J13: 0.12944 | K13: 0.53388 | L13: 0.15868 | M13: 0.00777 | N13: 0.00165 | O13: 0.0011 | P13: 0.00638 | Q13: ML-003 | R13: 工程短縮PJ | S13: 高橋 | T13: 45332
... A121: ME-00120 | B121: CH-2025-0120 | C121: 0.13776 | D121: 0.56195 | E121: 2.00995 | F121: 0.01626 | G121: 0.00439 | H121: 0.03043 | I121: 0 | J121: 0.18033 | K121: 0.53603 | L121: 0.17144 | M121: 0.01896 | N121: 0.00203 | O121: 0.00132 | P121: 0.00703 | Q121: ML-024 | R121: 工程短縮PJ | S121: 高橋 | T121: 45656

Sheet 熱延条件
A1: 熱延_key** | B1: 均熱温度[℃] | C1: 均熱時間[min] | D1: 仕上げ温度[℃] | E1: 入側板厚[mm] | F1: 出側板厚[mm] | G1: 冷却速度[℃/s] | H1: 保持温度[℃] | I1: 保持時間[min] | J1: 最終冷却 | K1: 設備 | L1: 試験依頼番号 | M1: ロット | N1: プロジェクト名 | O1: 登録者 | P1: 登録日
A2: HR-00001 | B2: 1168.038 | C2: 30 | D2: 904.873 | E2: 33.318 | F2: 3.459 | G2: 30 | H2: 600 | I2: 30 | J2: 炉冷 | K2: HR-LINE-1 | L2: RQ-HR-00001 | M2: HL-0001 | N2: 薄板高強度化PJ | O2: 山田 | P2: 45419
A3: HR-00002 | B3: 1165.427 | C3: 30 | D3: 911.495 | E3: 36.323 | F3: 3.355 | G3: 30 | H3: 600 | I3: 30 | J3: 炉冷 | K3: HR-LINE-1 | L3: RQ-HR-00002 | M3: HL-0001 | N3: 成形性改善PJ | O3: 高橋 | P3: 45422
A4: HR-00003 | B4: 1171.851 | C4: 30 | D4: 914.175 | E4: 36.937 | F4: 3.469 | G4: 30 | H4: 600 | I4: 30 | J4: 炉冷 | K4: HR-LINE-1 | L4: RQ-HR-00003 | M4: HL-0001 | N4: 成形性改善PJ | O4: 高橋 | P4: 45422
A5: HR-00004 | B5: 1209.325 | C5: 30 | D5: 890.908 | E5: 37.05 | F5: 3.884 | G5: 30 | H5: 600 | I5: 30 | J5: 炉冷 | K5: HR-LINE-1 | L5: RQ-HR-00004 | M5: HL-0001 | N5: 表面品質PJ | O5: 山田 | P5: 45425
A6: HR-00005 | B6: 1221.129 | C6: 30 | D6: 1276.129 | E6: 35.878 | F6: 3.426 | G6: 30 | H6: 600 | I6: 30 | J6: 炉冷 | K6: HR-LINE-1 | L6: RQ-HR-00005 | M6: HL-0001 | N6: 工程短縮PJ | O6: 高橋 | P6: 45428
A7: HR-00006 | B7: 1231.42 | C7: 30 | D7: 843.567 | E7: 39.666 | F7: 3.974 | G7: 30 | H7: 600 | I7: 30 | J7: 炉冷 | K7: HR-LINE-1 | L7: RQ-HR-00006 | M7: HL-0001 | N7: 工程短縮PJ | O7: 高橋 | P7: 45428
A8: HR-00007 | B8: 1247.689 | C8: 30 | D8: 854.116 | E8: 40.46 | F8: 4.142 | G8: 30 | H8: 600 | I8: 30 | J8: 炉冷 | K8: HR-LINE-1 | L8: RQ-HR-00007 | M8: HL-0001 | N8: 薄板高強度化PJ | O8: 山田 | P8: 45431
A9: HR-00008 | B9: 1162.043 | C9: 30 | D9: 918.38 | E9: 30.334 | F9: 3.211 | G9: 30 | H9: 600 | I9: 30 | J9: 炉冷 | K9: HR-LINE-1 | L9: RQ-HR-00008 | M9: HL-0002 | N9: 薄板高強度化PJ | O9: 山田 | P9: 45431
A10: HR-00009 | B10: 1177.3 | C10: 30 | D10: 918.958 | E10: 31.952 | F10: 3.343 | G10: 30 | H10: 600 | I10: 30 | J10: 炉冷 | K10: HR-LINE-1 | L10: RQ-HR-00009 | M10: HL-0002 | N10: 成形性改善PJ | O10: 高橋 | P10: 45434
A11: HR-00010 | B11: 1220.046 | C11: 30 | D11: 887.984 | E11: 35.171 | F11: 3.673 | G11: 30 | H11: 600 | I11: 30 | J11: 炉冷 | K11: HR-LINE-1 | L11: RQ-HR-00010 | M11: HL-0002 | N11: 成形性改善PJ | O11: 高橋 | P11: 45434
A12: HR-00011 | B12: 1228.406 | C12: 30 | D12: 865.958 | E12: 33.912 | F12: 3.777 | G12: 30 | H12: 600 | I12: 30 | J12: 炉冷 | K12: HR-LINE-1 | L12: RQ-HR-00011 | M12: HL-0002 | N12: 表面品質PJ | O12: 山田 | P12: 45437
A13: HR-00012 | B13: 1250.087 | C13: 30 | D13: 857.44 | E13: 39.014 | F13: 3.668 | G13: 30 | H13: 600 | I13: 30 | J13: 炉冷 | K13: HR-LINE-1 | L13: RQ-HR-00012 | M13: HL-0002 | N13: 工程短縮PJ | O13: 高橋 | P13: 45440
... A227: HR-00001 | B227: 1168.038 | C227: 30 | D227: 904.873 | E227: 33.318 | F227: 3.459 | G227: 30 | H227: 600 | I227: 30 | J227: 炉冷 | K227: HR-LINE-1 | L227: RQ-HR-00001 | M227: HL-0001 | N227: 薄板高強度化PJ | O227: 山田 | P227: 45419

Sheet 熱延組織
A1: 熱延組織_key** | B1: 画像リンク先 | C1: 撮影方法 | D1: 倍率 | E1: 腐食 | F1: 観察部位 | G1: 撮影日 | H1: 撮影者 | I1: 備考
A2: HMS-00001 | B2: images/hot/HR-00001_100x_ナイタール_板厚中央.png | C2: SEM | D2: 100x | E2: ナイタール | F2: 板厚中央 | G2: 45426 | H2: 鈴木
A3: HMS-00002 | B3: images/hot/HR-00002_100x_ナイタール_板厚中央.png | C3: SEM | D3: 100x | E3: ナイタール | F3: 板厚中央 | G3: 45429 | H3: 高橋
A4: HMS-00003 | B4: images/hot/HR-00002_500x_ナイタール_板厚中央.png | C4: SEM | D4: 500x | E4: ナイタール | F4: 板厚中央 | G4: 45430 | H4: 伊藤
A5: HMS-00004 | B5: images/hot/HR-00002_1000x_レペラ_表層.png | C5: SEM | D5: 1000x | E5: レペラ | F5: 表層 | G5: 45431 | H5: 渡辺
A6: HMS-00005 | B6: images/hot/HR-00003_100x_ナイタール_板厚中央.png | C6: SEM | D6: 100x | E6: ナイタール | F6: 板厚中央 | G6: 45429 | H6: 山田
A7: HMS-00006 | B7: images/hot/HR-00003_500x_ナイタール_板厚中央.png | C7: SEM | D7: 500x | E7: ナイタール | F7: 板厚中央 | G7: 45430 | H7: 佐藤
A8: HMS-00007 | B8: images/hot/HR-00003_1000x_レペラ_表層.png | C8: SEM | D8: 1000x | E8: レペラ | F8: 表層 | G8: 45431 | H8: 鈴木
A9: HMS-00008 | B9: images/hot/HR-00003_1000x_ナイタール_t/4.png | C9: SEM | D9: 1000x | E9: ナイタール | F9: t/4 | G9: 45432 | H9: 高橋
A10: HMS-00009 | B10: images/hot/HR-00008_100x_ナイタール_板厚中央.png | C10: SEM | D10: 100x | E10: ナイタール | F10: 板厚中央 | G10: 45438 | H10: 伊藤
A11: HMS-00010 | B11: images/hot/HR-00008_500x_ナイタール_板厚中央.png | C11: SEM | D11: 500x | E11: ナイタール | F11: 板厚中央 | G11: 45439 | H11: 渡辺
A12: HMS-00011 | B12: images/hot/HR-00010_100x_ナイタール_板厚中央.png | C12: SEM | D12: 100x | E12: ナイタール | F12: 板厚中央 | G12: 45441 | H12: 山田
A13: HMS-00012 | B13: images/hot/HR-00010_500x_ナイタール_板厚中央.png | C13: SEM | D13: 500x | E13: ナイタール | F13: 板厚中央 | G13: 45442 | H13: 佐藤
... A260: HMS-00259 | B260: images/hot/HR-00224_500x_ナイタール_板厚中央.png | C260: SEM | D260: 500x | E260: ナイタール | F260: 板厚中央 | G260: 45784 | H260: 鈴木

Sheet 熱延引張実績
A1: 熱延引張実績_key** | B1: 引張強さ[MPa] | C1: 降伏点[MPa] | D1: 0.2%耐力[Mpa] | E1: 一様伸び[%] | F1: 均一伸び[%] | G1: 試験片方向 | H1: 標点距離[mm] | I1: 破断位置 | J1: 試験日 | K1: 試験者 | L1: 備考
A2: HT-00001 | B2: 391.997 | C2: 311.436 | E2: 42.272 | F2: 27.856 | G2: L | H2: 50 | I2: A | J2: 45424 | K2: 高橋
A3: HT-00002 | B3: 389.841 | C3: 318.751 | E3: 43.063 | F3: 31.601 | G3: L | H3: 50 | I3: B | J3: 45425 | K3: 伊藤
A4: HT-00003 | B4: 400.149 | C4: 309.774 | E4: 41.757 | F4: 28.959 | G4: L | H4: 50 | I4: A | J4: 45427 | K4: 渡辺
A5: HT-00004 | B5: 454.947 | C5: 360.119 | E5: 40.362 | F5: 27.397 | G5: L | H5: 50 | I5: A | J5: 45427 | K5: 山田
A6: HT-00005 | B6: 464.696 | C6: 354.827 | E6: 41.156 | F6: 24.529 | G6: L | H6: 50 | I6: A | J6: 45428 | K6: 佐藤
A7: HT-00006 | B7: 557.689 | C7: 429.167 | E7: 34.938 | F7: 22.796 | G7: C | H7: 50 | I7: C | J7: 45430 | K7: 鈴木
A8: HT-00007 | B8: 576.778 | C8: 432.423 | E8: 36.081 | F8: 23.593 | G8: L | H8: 50 | I8: A | J8: 45431 | K8: 高橋
A9: HT-00008 | B9: 576.875 | C9: 440.515 | E9: 36.22 | F9: 24.668 | G9: L | H9: 50 | I9: B | J9: 45433 | K9: 伊藤
A10: HT-00009 | B10: 561.272 | C10: 436.783 | E10: 36.251 | F10: 24.817 | G10: C | H10: 50 | I10: A | J10: 45434 | K10: 渡辺
A11: HT-00010 | B11: 567.141 | C11: 434.828 | E11: 36.457 | F11: 24.253 | G11: L | H11: 50 | I11: A | J11: 45435 | K11: 山田
A12: HT-00011 | B12: 645.745 | C12: 491.605 | E12: 33.473 | F12: 21.551 | G12: L | H12: 50 | I12: A | J12: 45433 | K12: 佐藤
A13: HT-00012 | B13: 635.68 | C13: 497.118 | E13: 33.716 | F13: 23.745 | G13: C | H13: 50 | I13: A | J13: 45436 | K13: 鈴木
A14: HT-00013 | B14: 647.026 | C14: 492.745 | E14: 32.797 | F14: 20.617 | G14: L | H14: 50 | I14: A | J14: 45437 | K14: 高橋 | L14: 破断位置を要確認
A15: HT-00014 | B15: 388.518 | C15: 307.443 | E15: 42.76 | F15: 30.97 | G15: L | H15: 50 | I15: A | J15: 45436 | K15: 伊藤
A16: HT-00015 | B16: 382.322 | C16: 306.485 | E16: 42.618 | F16: 30.284 | G16: L | H16: 50 | I16: A | J16: 45437 | K16: 渡辺
A17: HT-00016 | B17: 389.166 | C17: 307.068 | E17: 43.725 | F17: 26.168 | G17: L | H17: 50 | I17: A | J17: 45439 | K17: 山田
A18: HT-00017 | B18: 389.518 | C18: 303.35 | E18: 42.519 | F18: 25.554 | G18: L | H18: 50 | I18: A | J18: 45440 | K18: 佐藤
A19: HT-00018 | B19: 384.097 | C19: 297.124 | E19: 43.529 | F19: 25.794 | G19: L | H19: 50 | I19: A | J19: 45441 | K19: 鈴木
A20: HT-00019 | B20: 461.859 | C20: 367.576 | E20: 40.145 | F20: 28.433 | G20: L | H20: 50 | I20: A | J20: 45439 | K20: 高橋
A21: HT-00020 | B21: 471.678 | C21: 370.061 | E21: 39.4 | F21: 23.659 | G21: L | H21: 50 | I21: A | J21: 45440 | K21: 伊藤
A22: HT-00021 | B22: 473.518 | D22: 366.375 | E22: 40.082 | F22: 29.409 | G22: L | H22: 50 | I22: A | J22: 45441 | K22: 渡辺
A23: HT-00022 | B23: 604.279 | D23: 463.814 | E23: 35.019 | F23: 25.181 | G23: L | H23: 50 | I23: A | J23: 45442 | K23: 山田
A24: HT-00023 | B24: 619.781 | D24: 466.113 | E24: 35.552 | F24: 20.593 | G24: L | H24: 50 | I24: A | J24: 45443 | K24: 佐藤
A25: HT-00024 | B25: 5223.301 | D25: 3827.571 | E25: -128.671 | F25: -75.807 | G25: L | H25: 50 | I25: A | J25: 45445 | K25: 鈴木
A26: HT-00025 | B26: 5361.703 | D26: 3826.708 | E26: -128.264 | F26: -83.983 | G26: L | H26: 50 | I26: A | J26: 45446 | K26: 高橋
A27: HT-00026 | B27: 378.724 | D27: 296.787 | E27: 41.536 | F27: 30.024 | G27: C | H27: 50 | I27: A | J27: 45448 | K27: 伊藤
A28: HT-00027 | B28: 363.868 | D28: 290.106 | E28: 43.087 | F28: 30.279 | G28: C | H28: 50 | I28: A | J28: 45449 | K28: 渡辺
A29: HT-00028 | B29: 376.853 | D29: 293.879 | E29: 42.77 | F29: 26.322 | G29: L | H29: 50 | I29: A | J29: 45451 | K29: 山田
A30: HT-00029 | B30: 376.957 | D30: 295.096 | E30: 43.183 | F30: 25.191 | G30: L | H30: 50 | I30: A | J30: 45452 | K30: 佐藤
A31: HT-00030 | B31: 509.126 | D31: 396.642 | E31: 37.862 | F31: 26.979 | G31: C | H31: 50 | I31: A | J31: 45451 | K31: 鈴木
A32: HT-00031 | B32: 504.237 | D32: 389.501 | E32: 39.416 | F32: 24.948 | G32: C | H32: 50 | I32: A | J32: 45452 | K32: 高橋
A33: HT-00032 | B33: 505.022 | D33: 390.74 | E33: 36.924 | F33: 21.948 | G33: C | H33: 50 | I33: A | J33: 45453 | K33: 伊藤
... A82: HT-00081 | B82: 659.629 | D82: 493.258 | E82: 34.335 | F82: 19.366 | G82: L | H82: 50 | I82: A | J82: 45497 | K82: 渡辺
A83: HT-00082 | B83: 383.748 | D83: 303.689 | E83: 42.262 | F83: 26.724 | G83: C | H83: 50 | I83: A | J83: 45496 | K83: 山田 | L83: 破断位置を要確認
A84: HT-00083 | B84: 387.55 | C84: 305.506 | E84: 41.974 | F84: 23.221 | G84: L | H84: 50 | I84: A | J84: 45497 | K84: 佐藤
A85: HT-00084 | B85: 376.204 | C85: 303.25 | E85: 42.648 | F85: 24.964 | G85: L | H85: 50 | I85: C | J85: 45499 | K85: 鈴木
A86: HT-00085 | B86: 383.488 | C86: 307.269 | E86: 41.757 | F86: 23.151 | G86: L | H86: 50 | I86: A | J86: 45500 | K86: 高橋
A87: HT-00086 | B87: 413.789 | C87: 321.948 | E87: 40.699 | F87: 28.228 | G87: C | H87: 50 | I87: A | J87: 45502 | K87: 伊藤
A88: HT-00087 | B88: 409.362 | C88: 321.808 | E88: 40.832 | F88: 23.123 | G88: C | H88: 50 | I88: A | J88: 45503 | K88: 渡辺
...

Sheet 焼鈍履歴
A1: 焼鈍履歴_key** | B1: チャンネル | C1: 工程 | D1: 到達時間[秒] | E1: 温度[℃] | F1: 昇温速度[℃/秒] | G1: 入力者 | H1: 備考
A2: AN-00001 | B2: 1 | C2: 開始 | D2: =IFERROR(VLOOKUP(C2,測定点マスタ!$E$2:$F$28,2,FALSE)/VLOOKUP(A2,'焼鈍条件-3CGL'!$A$2:$B$197,2,FALSE)*60,"") -> 0 | E2: 34.3 | F2: =IF(A2=A1,IFERROR((E2-E1)/(D2-D1),""),"") | G2: 山田 | H2: 設計値（CAL）
A3: AN-00001 | B3: 2 | C3: PHF | D3: =IFERROR(VLOOKUP(C3,測定点マスタ!$E$2:$F$28,2,FALSE)/VLOOKUP(A3,'焼鈍条件-3CGL'!$A$2:$B$197,2,FALSE)*60,"") -> 7.5161597 | E3: 164.1 | F3: =IF(A3=A2,IFERROR((E3-E2)/(D3-D2),""),"") -> 17.269457 | G3: 山田 | H3: 設計値（CAL）
A4: AN-00001 | B4: 3 | C4: RTH | D4: =IFERROR(VLOOKUP(C4,測定点マスタ!$E$2:$F$28,2,FALSE)/VLOOKUP(A4,'焼鈍条件-3CGL'!$A$2:$B$197,2,FALSE)*60,"") -> 17.036629 | E4: 630.5 | F4: =IF(A4=A3,IFERROR((E4-E3)/(D4-D3),""),"") -> 48.989183 | G4: 山田 | H4: 設計値（CAL）
A5: AN-00001 | B5: 4 | C5: RTS | D5: =IFERROR(VLOOKUP(C5,測定点マスタ!$E$2:$F$28,2,FALSE)/VLOOKUP(A5,'焼鈍条件-3CGL'!$A$2:$B$197,2,FALSE)*60,"") -> 22.047402 | E5: 764.8 | F5: =IF(A5=A4,IFERROR((E5-E4)/(D5-D4),""),"") -> 26.802251 | G5: 山田 | H5: 設計値（CAL）
A6: AN-00001 | B6: 5 | C6: 4BR入 | D6: =IFERROR(VLOOKUP(C6,測定点マスタ!$E$2:$F$28,2,FALSE)/VLOOKUP(A6,'焼鈍条件-3CGL'!$A$2:$B$197,2,FALSE)*60,"") -> 27.058175 | E6: 748.7 | F6: =IF(A6=A5,IFERROR((E6-E5)/(D6-D5),""),"") -> -3.213077 | G6: 山田 | H6: 設計値（CAL）
A7: AN-00001 | B7: 6 | C7: SCS | D7: =IFERROR(VLOOKUP(C7,測定点マスタ!$E$2:$F$28,2,FALSE)/VLOOKUP(A7,'焼鈍条件-3CGL'!$A$2:$B$197,2,FALSE)*60,"") -> 30.064639 | E7: 707.3 | F7: =IF(A7=A6,IFERROR((E7-E6)/(D7-D6),""),"") -> -13.77033 | G7: 山田 | H7: 設計値（CAL）
A8: AN-00001 | B8: 7 | C8: 1RCS入 | D8: =IFERROR(VLOOKUP(C8,測定点マスタ!$E$2:$F$28,2,FALSE)/VLOOKUP(A8,'焼鈍条件-3CGL'!$A$2:$B$197,2,FALSE)*60,"") -> 33.071103 | E8: 666.2 | F8: =IF(A8=A7,IFERROR((E8-E7)/(D8-D7),""),"") -> -13.670545 | G8: 山田 | H8: 設計値（CAL）
A9: AN-00001 | B9: 8 | C9: 1RCS | D9: =IFERROR(VLOOKUP(C9,測定点マスタ!$E$2:$F$28,2,FALSE)/VLOOKUP(A9,'焼鈍条件-3CGL'!$A$2:$B$197,2,FALSE)*60,"") -> 36.578644 | E9: 545 | F9: =IF(A9=A8,IFERROR((E9-E8)/(D9-D8),""),"") -> -34.55412 | G9: 山田 | H9: 設計値（CAL）
A10: AN-00001 | B10: 9 | C10: 2RCS | D10: =IFERROR(VLOOKUP(C10,測定点マスタ!$E$2:$F$28,2,FALSE)/VLOOKUP(A10,'焼鈍条件-3CGL'!$A$2:$B$197,2,FALSE)*60,"") -> 40.587263 | E10: 492.6 | F10: =IF(A10=A9,IFERROR((E10-E9)/(D10-D9),""),"") -> -13.071835 | G10: 山田 | H10: 設計値（CAL）
A11: AN-00001 | B11: 10 | C11: HDS | D11: =IFERROR(VLOOKUP(C11,測定点マスタ!$E$2:$F$28,2,FALSE)/VLOOKUP(A11,'焼鈍条件-3CGL'!$A$2:$B$197,2,FALSE)*60,"") -> 44.094804 | E11: 442.5 | F11: =IF(A11=A10,IFERROR((E11-E10)/(D11-D10),""),"") -> -14.28351 | G11: 山田 | H11: 設計値（CAL）
A12: AN-00001 | B12: 11 | C12: 3RCS | D12: =IFERROR(VLOOKUP(C12,測定点マスタ!$E$2:$F$28,2,FALSE)/VLOOKUP(A12,'焼鈍条件-3CGL'!$A$2:$B$197,2,FALSE)*60,"") -> 48.6045 | E12: 321.9 | F12: =IF(A12=A11,IFERROR((E12-E11)/(D12-D11),""),"") -> -26.74238 | G12: 山田 | H12: 設計値（CAL）
A13: AN-00001 | B13: 12 | C13: OAS入側 | D13: =IFERROR(VLOOKUP(C13,測定点マスタ!$E$2:$F$28,2,FALSE)/VLOOKUP(A13,'焼鈍条件-3CGL'!$A$2:$B$197,2,FALSE)*60,"") -> 54.617427 | E13: 497.5 | F13: =IF(A13=A12,IFERROR((E13-E12)/(D13-D12),""),"") -> 29.203743 | G13: 山田 | H13: 設計値（CAL）
... A3508: AN-00196 | B3508: 19 | C3508: 水冷 | D3508: =IFERROR(VLOOKUP(C3508,測定点マスタ!$E$2:$F$28,2,FALSE)/VLOOKUP(A3508,'焼鈍条件-3CGL'!$A$2:$B$197,2,FALSE)*60,"") -> 139.40782 | E3508: 74.7 | F3508: =IF(A3508=A3507,IFERROR((E3508-E3507)/(D3508-D3507),""),"") -> -9.0645676 | G3508: 高橋 | H3508: 設計値（GI）

Sheet 焼鈍条件-3CGL
A1: 焼鈍条件-3CGL_key** | B1: LS[mpm] | C1: 開始[℃] | D1: PHF[℃] | E1: DFF[℃] | F1: RTH[℃] | G1: RTS[℃] | H1: 4BR入[℃] | I1: SCS[℃] | J1: 1RCS入[℃] | K1: 1RCS[℃] | L1: 2RCS[℃] | M1: HDS[℃] | N1: 3RCS入[℃] | O1: 3RCS[℃] | P1: ダミー[℃] | Q1: 1RHF[℃] | R1: OAS入側[℃] | S1: OAS入側中間[℃] | T1: OAS出口[℃] | U1: 2RHF[℃] | V1: FCS[℃] | W1: GF入[℃] | X1: GF[℃] | Y1: GHF[℃] | Z1: 高棟トップロール[℃] | AA1: AJC[℃] | AB1: 水冷入[℃] | AC1: 水冷[℃] | AD1: 試験依頼番号 | AE1: ロット | AF1: プロジェクト名 | AG1: 登録者 | AH1: 登録日 | AI1: 備考
A2: AN-00001 | B2: 119.742 | C2: 34.3 | D2: 164.1 | F2: 630.5 | G2: 764.8 | H2: 748.7 | I2: 707.3 | J2: 666.2 | K2: 545 | L2: 492.6 | M2: 442.5 | O2: 321.9 | R2: 497.5 | T2: 500.3 | U2: 510.4 | V2: 245.6 | AA2: 179.4 | AB2: 104.3 | AC2: 48.3 | AD2: RQ-AN-00001 | AE2: AL-0001 | AF2: 表面品質PJ | AG2: 山田 | AH2: 45749
A3: AN-00002 | B3: 125.948 | C3: 39.4 | D3: 187.6 | F3: 638.1 | G3: 771.9 | H3: 726.9 | I3: 717.5 | K3: 562 | L3: 456.9 | M3: 440.4 | N3: 404.5 | O3: 325.7 | R3: 511.7 | T3: 493.2 | V3: 248.1 | AA3: 175.3 | AB3: 101 | AC3: 53 | AD3: RQ-AN-00002 | AE3: AL-0001 | AF3: 工程短縮PJ | AG3: 高橋 | AH3: 45752
A4: AN-00003 | B4: 111.049 | C4: 35.5 | D4: 168.3 | F4: 659.2 | G4: 803.8 | I4: 751.6 | K4: 585.6 | L4: 468.6 | M4: 455.3 | N4: 407.4 | O4: 334.6 | R4: 533.6 | T4: 519.2 | V4: 272.7 | W4: 458.9 | AA4: 277.4 | AC4: 40 | AD4: RQ-AN-00003 | AE4: AL-0001 | AF4: 薄板高強度化PJ | AG4: 山田 | AH4: 45755
A5: AN-00004 | B5: 87.738 | C5: 26.5 | D5: 187.6 | F5: 687.6 | G5: 822.8 | H5: 796 | I5: 763.7 | K5: 600.2 | L5: 525.3 | M5: 484.2 | O5: 349.1 | R5: 536.8 | S5: 531.8 | T5: 509 | V5: 259.5 | AA5: 242.4 | AC5: 63.6 | AD5: RQ-AN-00004 | AE5: AL-0001 | AF5: 成形性改善PJ | AG5: 高橋 | AH5: 45758
A6: AN-00005 | B6: 70.279 | C6: 39.9 | D6: 174.2 | F6: 667.5 | G6: 825.7 | I6: 772.8 | K6: 622.8 | L6: 488.3 | M6: 442.1 | O6: 340.9 | R6: 528.2 | T6: 510.3 | V6: 276.9 | W6: 452.4 | X6: 546.5 | Y6: 531.3 | AA6: 208.4 | AC6: 53.7 | AD6: RQ-AN-00005 | AE6: AL-0001 | AF6: 表面品質PJ | AG6: 山田 | AH6: 45761
A7: AN-00006 | B7: 60.696 | C7: 38.1 | D7: 189.9 | F7: 656.9 | G7: 790.3 | I7: 712.1 | K7: 581.2 | L7: 493.9 | M7: 455 | O7: 333.9 | R7: 498 | T7: 484.6 | V7: 251 | W7: 460.8 | X7: 543.3 | Y7: 533.2 | AA7: 188.1 | AC7: 46.8 | AD7: RQ-AN-00006 | AE7: AL-0001 | AF7: 薄板高強度化PJ | AG7: 山田 | AH7: 45767
A8: AN-00007 | B8: 133.615 | C8: 37.7 | D8: 170 | E8: 335.9 | F8: 621.7 | G8: 742.5 | H8: 717.8 | I8: 691.3 | K8: 551.9 | L8: 470.5 | M8: 417.6 | O8: 329 | R8: 493.2 | S8: 498.8 | T8: 478.6 | V8: 252.6 | W8: 467.2 | Z8: 372.4 | AA8: 266.8 | AB8: 135.7 | AC8: 52.2 | AD8: RQ-AN-00007 | AE8: AL-0001 | AF8: 成形性改善PJ | AG8: 高橋 | AH8: 45770
A9: AN-00008 | B9: 138.33 | C9: 35.5 | D9: 184.8 | F9: 612.7 | G9: 768.1 | H9: 733 | I9: 694.1 | K9: 558.2 | L9: 471.7 | M9: 429.9 | N9: 378.9 | O9: 339.9 | R9: 493.1 | T9: 482.7 | V9: 244.5 | W9: 463.1 | Z9: 361.8 | AA9: 269.4 | AC9: 69.9 | AD9: RQ-AN-00008 | AE9: AL-0001 | AF9: 表面品質PJ | AG9: 山田 | AH9: 45773
A10: AN-00009 | B10: 128.024 | C10: 25.4 | D10: 183.5 | F10: 640.9 | G10: 806.7 | I10: 715.9 | K10: 588.1 | L10: 502 | M10: 456.9 | O10: 338.1 | R10: 541.3 | T10: 536.6 | V10: 278 | W10: 466.7 | X10: 528.8 | Y10: 520.3 | AA10: 186.2 | AC10: 58.2 | AD10: RQ-AN-00009 | AE10: AL-0001 | AF10: 工程短縮PJ | AG10: 高橋 | AH10: 45776
A11: AN-00010 | B11: 73.141 | C11: 31.8 | D11: 198.1 | F11: 694 | G11: 852.2 | I11: 763.2 | K11: 650.1 | L11: 506.7 | M11: 461.3 | O11: 372.2 | Q11: 549.4 | R11: 548 | T11: 525.1 | V11: 266.3 | W11: 458 | AA11: 173.6 | AC11: 35.7 | AD11: RQ-AN-00010 | AE11: AL-0002 | AF11: 薄板高強度化PJ | AG11: 山田 | AH11: 45779
A12: AN-00011 | B12: 55.077 | C12: 37.5 | D12: 174.1 | E12: 379.5 | F12: 695.4 | G12: 851 | I12: 803.8 | K12: 615.8 | L12: 543.1 | M12: 476.2 | O12: 377.1 | R12: 541 | T12: 525.7 | V12: 278.3 | W12: 460.6 | X12: 513.5 | Y12: 494.3 | AA12: 202.4 | AC12: 62.4 | AD12: RQ-AN-00011 | AE12: AL-0002 | AF12: 成形性改善PJ | AG12: 高橋 | AH12: 45782
A13: AN-00012 | B13: 70.447 | C13: 37.4 | D13: 198 | F13: 709.2 | G13: 839.1 | I13: 783.9 | K13: 627.6 | L13: 536.6 | M13: 492.6 | N13: 423.9 | O13: 376.2 | R13: 533.4 | T13: 519.7 | V13: 261.3 | W13: 463.6 | AA13: 196.8 | AB13: 137.8 | AC13: 45.6 | AD13: RQ-AN-00012 | AE13: AL-0002 | AF13: 成形性改善PJ | AG13: 高橋 | AH13: 45782
A14: AN-00013 | B14: 131.732 | C14: 34 | D14: 182.7 | F14: 630.9 | G14: 780.4 | H14: 749.3 | I14: 730.4 | K14: 571.6 | L14: 481.8 | M14: 440.8 | O14: 321.9 | R14: 506.5 | T14: 494.1 | V14: 252.1 | AA14: 181.4 | AB14: 129.1 | AC14: 74 | AD14: RQ-AN-00013 | AE14: AL-0002 | AF14: 工程短縮PJ | AG14: 高橋 | AH14: 45788
A15: AN-00014 | B15: 104.112 | C15: 35.4 | D15: 175.1 | F15: 680.2 | G15: 837.4 | I15: 787.8 | K15: 635.3 | L15: 521.9 | M15: 491.5 | O15: 371.7 | Q15: 518.1 | R15: 540.5 | T15: 521.8 | V15: 287.6 | W15: 455.6 | X15: 549.9 | Y15: 522.1 | AA15: 286.3 | AC15: 67.8 | AD15: RQ-AN-00014 | AE15: AL-0002 | AF15: 成形性改善PJ | AG15: 高橋 | AH15: 45794
A16: AN-00015 | B16: 98.849 | C16: 37.3 | D16: 200.5 | F16: 708.7 | G16: 866.2 | I16: 802.9 | K16: 665 | L16: 552.2 | M16: 480.7 | N16: 421.6 | O16: 380.3 | Q16: 540.9 | R16: 575.8 | T16: 559.7 | V16: 277.1 | AA16: 267 | AB16: 141.4 | AC16: 66.1 | AD16: RQ-AN-00015 | AE16: AL-0002 | AF16: 表面品質PJ | AG16: 山田 | AH16: 45797
A17: AN-00016 | B17: 86.422 | C17: 28.5 | D17: 183.5 | F17: 692.8 | G17: 853 | I17: 781 | J17: 766.5 | K17: 635.3 | L17: 508.8 | M17: 497.2 | O17: 362 | R17: 574.1 | T17: 574.9 | U17: 586.1 | V17: 302.5 | Z17: 365.8 | AA17: 281.2 | AB17: 99.4 | AC17: 58.8 | AD17: RQ-AN-00016 | AE17: AL-0002 | AF17: 工程短縮PJ | AG17: 高橋 | AH17: 45800
A18: AN-00017 | B18: 80.88 | C18: 37.3 | D18: 207 | F18: 732.1 | G18: 878.3 | I18: 808.9 | K18: 643.1 | L18: 516.7 | M18: 479.6 | N18: 439.8 | O18: 383.2 | Q18: 563.2 | R18: 578.7 | S18: 580.4 | T18: 569.2 | U18: 583.7 | V18: 273.6 | Z18: 406.5 | AA18: 243.1 | AB18: 136.3 | AC18: 63.9 | AD18: RQ-AN-00017 | AE18: AL-0002 | AF18: 薄板高強度化PJ | AG18: 山田 | AH18: 45803
A19: AN-00018 | B19: 134.826 | C19: 28.2 | D19: 164.3 | E19: 312.9 | F19: 608.6 | G19: 720.9 | I19: 672.2 | K19: 533.4 | L19: 432.8 | M19: 400.6 | O19: 314.9 | R19: 461.1 | T19: 447.7 | V19: 231.8 | AA19: 202.8 | AC19: 54.5 | AD19: RQ-AN-00018 | AE19: AL-0002 | AF19: 成形性改善PJ | AG19: 高橋 | AH19: 45806
A20: AN-00019 | B20: 2.325 | C20: 26.3 | D20: 178.9 | F20: 632 | G20: 782.3 | I20: 710.7 | K20: 599.7 | L20: 495.8 | M20: 454.7 | O20: 345.9 | R20: 504 | T20: 496.1 | V20: 254.9 | W20: 453.5 | X20: 552.2 | Y20: 529.4 | Z20: 321.2 | AA20: 201.4 | AC20: 50.7 | AD20: RQ-AN-00019 | AE20: AL-0002 | AF20: 表面品質PJ | AG20: 山田 | AH20: 45809 | AI20: m/s値をm/min列に入力した疑い
A21: AN-00020 | B21: 161.951 | C21: 30.6 | D21: 155.3 | F21: 590.2 | G21: 722.2 | I21: 672.7 | K21: 543.9 | L21: 422.5 | M21: 425.8 | O21: 313.6 | R21: 486.9 | S21: 487.6 | T21: 474.6 | U21: 499.8 | V21: 226.1 | W21: 461.4 | X21: 537.2 | Y21: 525.3 | AA21: 178.4 | AB21: 139.6 | AC21: 35.8 | AD21: RQ-AN-00020 | AE21: AL-0003 | AF21: 表面品質PJ | AG21: 山田 | AH21: 45809
A22: AN-00021 | B22: 146.216 | C22: 38.7 | D22: 171.5 | F22: 651.9 | G22: 794.8 | H22: 764.6 | I22: 741.1 | J22: 691.7 | K22: 574.5 | L22: 470.9 | M22: 450.3 | N22: 403.9 | O22: 327.9 | R22: 523 | S22: 524 | T22: 515.3 | U22: 543.4 | V22: 272.1 | Z22: 381.1 | AA22: 189.3 | AC22: 74.1 | AD22: RQ-AN-00021 | AE22: AL-0003 | AF22: 工程短縮PJ | AG22: 高橋 | AH22: 45812
A23: AN-00022 | B23: 105.106 | C23: 33 | D23: 179.4 | E23: 339 | F23: 658.9 | G23: 786.4 | I23: 705.7 | K23: 574 | L23: 459.7 | M23: 431.8 | O23: 336.9 | R23: 520 | S23: 527.6 | T23: 519.5 | V23: 268.6 | W23: 459.8 | AA23: 274.1 | AC23: 59.6 | AD23: RQ-AN-00022 | AE23: AL-0003 | AF23: 成形性改善PJ | AG23: 高橋 | AH23: 45818
A24: AN-00023 | B24: 85.469 | C24: 37.5 | D24: 179.2 | F24: 682.5 | G24: 828.3 | I24: 737.4 | K24: 597.6 | L24: 493.8 | M24: 459.7 | O24: 342.3 | Q24: 523.9 | R24: 537.6 | T24: 530.1 | V24: 293.9 | W24: 453.8 | X24: 510.1 | Y24: 489.9 | AA24: 238.7 | AC24: 70.9 | AD24: RQ-AN-00023 | AE24: AL-0003 | AF24: 表面品質PJ | AG24: 山田 | AH24: 45821
A25: AN-00024 | B25: 81.792 | C25: 38.2 | D25: 184.3 | E25: 379.8 | F25: 657.4 | G25: 821.6 | I25: 779.4 | K25: 614.4 | L25: 482 | M25: 463.2 | O25: 336.4 | R25: 539.3 | T25: 541.3 | V25: 286.1 | W25: 467.5 | AA25: 222.4 | AC25: 70.6 | AD25: RQ-AN-00024 | AE25: AL-0003 | AF25: 工程短縮PJ | AG25: 高橋 | AH25: 45824
A26: AN-00025 | B26: 77.112 | C26: 36.3 | D26: 203.5 | F26: 686.2 | G26: 857.6 | I26: 793.1 | J26: 774.4 | K26: 618.6 | L26: 503.8 | M26: 500.8 | N26: 418.7 | O26: 358.1 | Q26: 547 | R26: 548.4 | T26: 531.5 | U26: 599.4 | V26: 295 | Z26: 338.9 | AA26: 199.4 | AB26: 88.2 | AC26: 66.7 | AD26: RQ-AN-00025 | AE26: AL-0003 | AF26: 工程短縮PJ | AG26: 高橋 | AH26: 45824
A27: AN-00026 | B27: 116.786 | C27: 29 | D27: 153.7 | E27: 333.3 | F27: 640.1 | G27: 773 | I27: 719.3 | K27: 591 | L27: 458.1 | M27: 451.3 | O27: 318.1 | R27: 501.4 | T27: 494 | U27: 527 | V27: 252.6 | Z27: 340.5 | AA27: 186.7 | AC27: 64.5 | AD27: RQ-AN-00026 | AE27: AL-0003 | AF27: 薄板高強度化PJ | AG27: 山田 | AH27: 45827
A28: AN-00027 | B28: 115.661 | C28: 38.2 | D28: 165.7 | F28: 647 | G28: 798.8 | H28: 772.1 | I28: 745 | J28: 708.6 | K28: 580.8 | L28: 472.3 | M28: 462.6 | O28: 363 | R28: 507.1 | T28: 497.1 | V28: 258.8 | AA28: 219.9 | AC28: 72.6 | AD28: RQ-AN-00027 | AE28: AL-0003 | AF28: 成形性改善PJ | AG28: 高橋 | AH28: 45830
A29: AN-00028 | B29: 105.946 | C29: 36.8 | D29: 160.8 | E29: 374.8 | F29: 662.3 | G29: 816.5 | I29: 728.1 | K29: 620.2 | L29: 478 | M29: 444.3 | N29: 390.3 | O29: 364.2 | Q29: 527.4 | R29: 527.3 | T29: 522.3 | V29: 274.7 | W29: 466.1 | AA29: 206.1 | AB29: 121.2 | AC29: 36.3 | AD29: RQ-AN-00028 | AE29: AL-0003 | AF29: 表面品質PJ | AG29: 山田 | AH29: 45833
A30: AN-00029 | B30: 117.751 | C30: 33.6 | D30: 192.6 | F30: 659.6 | G30: 799.8 | H30: 762.1 | I30: 732.7 | K30: 598.5 | L30: 461.2 | M30: 463.8 | O30: 344.2 | R30: 533.4 | T30: 519.2 | V30: 280.1 | W30: 456.3 | X30: 542.3 | Y30: 534 | AA30: 284.5 | AB30: 144.4 | AC30: 62.4 | AD30: RQ-AN-00029 | AE30: AL-0003 | AF30: 工程短縮PJ | AG30: 高橋 | AH30: 45836
A31: AN-00030 | B31: 72.233 | C31: 34.7 | D31: 181.6 | F31: 691.2 | G31: 863.6 | H31: 815.8 | I31: 812.9 | K31: 622.2 | L31: 521 | M31: 501.8 | O31: 355.4 | R31: 556.8 | T31: 529.6 | V31: 292 | W31: 455 | Z31: 367.5 | AA31: 211.5 | AB31: 139.2 | AC31: 52.1 | AD31: RQ-AN-00030 | AE31: AL-0004 | AF31: 成形性改善PJ | AG31: 高橋 | AH31: 45842
A32: AN-00031 | B32: 72.821 | C32: 28.1 | D32: 199.2 | F32: 673.1 | G32: 848.1 | I32: 768.7 | K32: 607.8 | L32: 505.8 | M32: 466 | N32: 410.9 | O32: 366.9 | R32: 564.4 | T32: 544.6 | V32: 289.1 | Z32: 394.7 | AA32: 249.7 | AB32: 120.7 | AC32: 74.8 | AD32: RQ-AN-00031 | AE32: AL-0004 | AF32: 表面品質PJ | AG32: 山田 | AH32: 45845
A33: AN-00032 | B33: 164.295 | C33: 37.4 | D33: 181.8 | E33: 373 | F33: 637.9 | G33: 799.4 | I33: 750.2 | K33: 603.9 | L33: 500.6 | M33: 438.1 | O33: 344.4 | Q33: 488.7 | R33: 521.9 | T33: 505 | V33: 281.2 | W33: 455.8 | AA33: 271.3 | AB33: 140.8 | AC33: 69.2 | AD33: RQ-AN-00032 | AE33: AL-0004 | AF33: 工程短縮PJ | AG33: 高橋 | AH33: 45848
A34: AN-00033 | B34: 100.417 | C34: 25.9 | D34: 173.3 | F34: 629 | G34: 783.7 | I34: 729.3 | K34: 588.8 | L34: 481.3 | M34: 433.3 | O34: 341.1 | R34: 508.7 | T34: 496 | V34: 252 | W34: 461.7 | X34: 515 | Y34: 502.2 | AA34: 177.7 | AC34: 70.1 | AD34: RQ-AN-00033 | AE34: AL-0004 | AF34: 薄板高強度化PJ | AG34: 山田 | AH34: 45851
A35: AN-00034 | B35: 102.913 | C35: 27.8 | D35: 184.9 | E35: 378.8 | F35: 679.9 | G35: 822.1 | I35: 772.5 | J35: 728.4 | K35: 620.4 | L35: 484.5 | M35: 448.3 | O35: 342.6 | Q35: 538.2 | R35: 527.1 | T35: 510.8 | U35: 575.2 | V35: 274.6 | W35: 467.9 | Z35: 346 | AA35: 210.4 | AC35: 37.1 | AD35: RQ-AN-00034 | AE35: AL-0004 | AF35: 表面品質PJ | AG35: 山田 | AH35: 45857
A36: AN-00035 | B36: 99.867 | C36: 31.9 | D36: 179.7 | F36: 668.9 | G36: 840.5 | H36: 789.5 | I36: 753.2 | K36: 639.5 | L36: 504.7 | M36: 459.8 | O36: 347.8 | R36: 543.8 | T36: 533.3 | U36: 586.7 | V36: 277.2 | W36: 462.3 | AA36: 223.5 | AC36: 42.4 | AD36: RQ-AN-00035 | AE36: AL-0004 | AF36: 工程短縮PJ | AG36: 高橋 | AH36: 45860
A37: AN-00036 | B37: 72.009 | C37: 32.4 | D37: 171.9 | E37: 386.5 | F37: 681.7 | G37: 852.6 | I37: 795.5 | K37: 609.6 | L37: 522.6 | M37: 475.8 | O37: 366.6 | R37: 568.1 | T37: 569.3 | V37: 268.5 | W37: 462.7 | X37: 537.2 | Y37: 520.9 | Z37: 342.2 | AA37: 247.7 | AB37: 116.3 | AC37: 58.6 | AD37: RQ-AN-00036 | AE37: AL-0004 | AF37: 薄板高強度化PJ | AG37: 山田 | AH37: 45863
A38: AN-00037 | B38: 62.562 | C38: 31.7 | D38: 204.1 | E38: 422.8 | F38: 692.2 | G38: 860.9 | I38: 776.3 | K38: 657.9 | L38: 547.4 | M38: 465.7 | N38: 439.5 | O38: 368.1 | R38: 554.6 | T38: 544.9 | V38: 271.7 | W38: 456 | X38: 514.2 | Y38: 489.9 | AA38: 247.4 | AC38: 40.4 | AD38: RQ-AN-00037 | AE38: AL-0004 | AF38: 表面品質PJ | AG38: 山田 | AH38: 45869
A39: AN-00038 | B39: 76.806 | C39: 34 | D39: 194.7 | F39: 688.1 | G39: 854.3 | H39: 831 | I39: 773.9 | K39: 653.7 | L39: 542.1 | M39: 492.3 | O39: 347.8 | R39: 538.7 | S39: 539.4 | T39: 517.5 | V39: 285.5 | Z39: 388.1 | AA39: 272.7 | AC39: 69.9 | AD39: RQ-AN-00038 | AE39: AL-0004 | AF39: 表面品質PJ | AG39: 山田 | AH39: 45869
A40: AN-00039 | B40: 74.157 | C40: 35.9 | D40: 193.6 | E40: 370.5 | F40: 710.2 | G40: 851.6 | H40: 806.7 | I40: 801.7 | J40: 733 | K40: 654.6 | L40: 495.9 | M40: 483.8 | N40: 433.2 | O40: 358.2 | R40: 552.7 | T40: 539.7 | V40: 300.3 | Z40: 345.6 | AA40: 272.5 | AB40: 119.3 | AC40: 51.6 | AD40: RQ-AN-00039 | AE40: AL-0004 | AF40: 工程短縮PJ | AG40: 高橋 | AH40: 45872
...

Sheet 焼鈍穴拡げ実績
A1: 焼鈍穴拡げ実績_key** | B1: 穴拡げ率[%] | C1: 打ち抜き径[mm] | D1: ダイス径[mm] | E1: 試験日 | F1: 試験者
A2: HE-00001 | B2: 116.824 | C2: 10 | D2: 10.3 | E2: 45757 | F2: 渡辺
A3: HE-00002 | B3: 120.548 | C3: 10 | D3: 10.3 | E3: 45758 | F3: 山田
A4: HE-00003 | B4: 118.893 | C4: 10 | D4: 10.3 | E4: 45759 | F4: 佐藤
A5: HE-00004 | B5: 120.566 | C5: 10 | D5: 10.3 | E5: 45760 | F5: 鈴木
A6: HE-00005 | B6: 119.594 | C6: 10 | D6: 10.3 | E6: 45761 | F6: 高橋
A7: HE-00006 | B7: 112.901 | C7: 10 | D7: 10.3 | E7: 45762 | F7: 伊藤
A8: HE-00007 | B8: 122.065 | C8: 10 | D8: 10.3 | E8: 45763 | F8: 渡辺
A9: HE-00008 | B9: 115.387 | C9: 10 | D9: 10.3 | E9: 45763 | F9: 山田
A10: HE-00009 | B10: 110.459 | C10: 10 | D10: 10.3 | E10: 45764 | F10: 佐藤
A11: HE-00010 | B11: 109 | C11: 10 | D11: 10.3 | E11: 45765 | F11: 鈴木
A12: HE-00011 | B12: 113.407 | C12: 10 | D12: 10.3 | E12: 45766 | F12: 高橋
A13: HE-00012 | B13: 109.707 | C13: 10 | D13: 10.3 | E13: 45767 | F13: 伊藤
... A41: HE-00040 | B41: 93.119 | C41: 10 | D41: 10.3 | E41: 45805 | F41: 鈴木
A42: HE-00041 | C42: 10 | D42: 10.3 | E42: 45806 | F42: 高橋
A43: HE-00042 | C43: 10 | D43: 10.3 | E43: 45807 | F43: 伊藤
A44: HE-00043 | C44: 10 | D44: 10.3 | E44: 45808 | F44: 渡辺
A45: HE-00044 | C45: 10 | D45: 10.3 | E45: 45811 | F45: 山田
A46: HE-00045 | C46: 10 | D46: 10.3 | E46: 45812 | F46: 佐藤
A47: HE-00046 | C47: 10 | D47: 10.3 | E47: 45813 | F47: 鈴木
A48: HE-00047 | C48: 10 | D48: 10.3 | E48: 45814 | F48: 高橋
A49: HE-00048 | C49: 10 | D49: 10.3 | E49: 45814 | F49: 伊藤
A50: HE-00049 | C50: 10 | D50: 10.3 | E50: 45815 | F50: 渡辺
A51: HE-00050 | C51: 10 | D51: 10.3 | E51: 45816 | F51: 山田
A52: HE-00051 | C52: 10 | D52: 10.3 | E52: 45817 | F52: 佐藤
A53: HE-00052 | C53: 10 | D53: 10.3 | E53: 45817 | F53: 鈴木
... A55: HE-00054 | C55: 10 | D55: 10.3 | E55: 45819 | F55: 伊藤
A56: HE-00055 | B56: 117.424 | C56: 10 | D56: 10.3 | E56: 45820 | F56: 渡辺
A57: HE-00056 | B57: 120.141 | C57: 10 | D57: 10.3 | E57: 45821 | F57: 山田
A58: HE-00057 | B58: 117.626 | C58: 10 | D58: 10.3 | E58: 45820 | F58: 佐藤
A59: HE-00058 | B59: 115.924 | C59: 10 | D59: 10.3 | E59: 45821 | F59: 鈴木
A60: HE-00059 | B60: 120.713 | C60: 10 | D60: 10.3 | E60: 45822 | F60: 高橋
A61: HE-00060 | B61: 105.838 | C61: 10 | D61: 10.3 | E61: 45826 | F61: 伊藤
A62: HE-00061 | B62: 108.799 | C62: 10 | D62: 10.3 | E62: 45827 | F62: 渡辺
A63: HE-00062 | B63: 107.663 | C63: 10 | D63: 10.3 | E63: 45828 | F63: 山田
A64: HE-00063 | B64: 102.167 | C64: 10 | D64: 10.3 | E64: 45829 | F64: 佐藤
A65: HE-00064 | B65: 93.687 | C65: 10 | D65: 10.3 | E65: 45829 | F65: 鈴木
A66: HE-00065 | B66: 99.334 | C66: 10 | D66: 10.3 | E66: 45830 | F66: 高橋
A67: HE-00066 | B67: 95.538 | C67: 10 | D67: 10.3 | E67: 45831 | F67: 伊藤
... A533: HE-00532 | B533: 79.716 | C533: 10 | D533: 10.3 | E533: 45779 | F533: 鈴木

Sheet 焼鈍引張実績
A1: 焼鈍引張実績_key** | B1: 引張強さ[MPa] | C1: 降伏点[MPa] | D1: 0.2耐力点[MPa] | E1: 伸び_突き合わせ[%] | F1: 一様伸び[%] | G1: n値[-] | H1: 破断位置 | I1: 試験日 | J1: 試験者 | K1: 備考
A2: TT-00001 | B2: 318.296 | C2: 251.382 | E2: 50.444 | F2: 28.94 | G2: 0.243 | H2: A | I2: 45758 | J2: 伊藤
A3: TT-00002 | B3: 323.801 | C3: 256.175 | E3: 51.279 | F3: 31.742 | G3: 0.232 | H3: A | I3: 45759 | J3: 渡辺
A4: TT-00003 | B4: 371.338 | C4: 293.787 | E4: 47.701 | F4: 29.888 | G4: 0.227 | H4: A | I4: 45761 | J4: 山田
A5: TT-00004 | B5: 372.223 | C5: 297.99 | E5: 47.512 | F5: 27.592 | G5: 0.234 | H5: A | I5: 45762 | J5: 佐藤
A6: TT-00005 | B6: 493.606 | C6: 384.814 | E6: 43.048 | F6: 27.022 | G6: 0.183 | H6: A | I6: 45764 | J6: 鈴木
A7: TT-00006 | B7: 485.102 | C7: 378.695 | E7: 42.254 | F7: 23.936 | G7: 0.198 | H7: C | I7: 45765 | J7: 高橋
A8: TT-00007 | B8: 643.969 | C8: 495.207 | E8: 34.512 | F8: 24.337 | G8: 0.19 | H8: A | I8: 45773 | J8: 伊藤
A9: TT-00008 | B9: 342.973 | C9: 270.901 | E9: 49.316 | F9: 29.964 | G9: 0.215 | H9: A | I9: 45776 | J9: 渡辺
A10: TT-00009 | B10: 339.336 | D10: 260.395 | E10: 50.073 | F10: 31.174 | G10: 0.233 | H10: A | I10: 45777 | J10: 山田
A11: TT-00010 | B11: 317.345 | D11: 251.361 | E11: 51.462 | F11: 30.494 | G11: 0.231 | H11: A | I11: 45779 | J11: 佐藤
A12: TT-00011 | B12: 315.192 | D12: 255.811 | E12: 50.294 | F12: 32.537 | G12: 0.222 | H12: A | I12: 45780 | J12: 鈴木
A13: TT-00012 | B13: 424.541 | D13: 330.239 | E13: 45.201 | F13: 25.604 | G13: 0.212 | H13: A | I13: 45782 | J13: 高橋
A14: TT-00013 | B14: 430.986 | D14: 337.671 | E14: 44.232 | F14: 24.552 | G14: 0.227 | H14: A | I14: 45783 | J14: 伊藤
A15: TT-00014 | B15: 558.479 | D15: 429.482 | E15: 41.288 | F15: 23.546 | G15: 0.221 | H15: A | I15: 45785 | J15: 渡辺
A16: TT-00015 | B16: 559.139 | D16: 423.591 | E16: 41.98 | F16: 29.274 | G16: 0.204 | H16: A | I16: 45786 | J16: 山田
A17: TT-00016 | B17: 5236.492 | D17: 3951.208 | E17: -145.721 | F17: -97.378 | G17: 0.08 | H17: A | I17: 45788 | J17: 佐藤
A18: TT-00017 | B18: 5166.24 | D18: 3814.019 | E18: -145.857 | F18: -84.359 | G18: 0.08 | H18: A | I18: 45789 | J18: 鈴木
A19: TT-00018 | B19: 293.81 | D19: 242.682 | E19: 50.784 | F19: 30.884 | G19: 0.235 | H19: A | I19: 45794 | J19: 高橋
A20: TT-00019 | B20: 295.669 | D20: 236.788 | E20: 51.307 | F20: 28.699 | G20: 0.213 | H20: A | I20: 45795 | J20: 伊藤
A21: TT-00020 | B21: 413.554 | D21: 331.645 | E21: 45.611 | F21: 29.172 | G21: 0.223 | H21: A | I21: 45800 | J21: 渡辺
... A42: TT-00041 | B42: 397.953 | D42: 312.936 | E42: 47.413 | F42: 27.263 | G42: 0.216 | H42: A | I42: 45837 | J42: 鈴木
A43: TT-00042 | B43: 0.422 | D43: 341.102 | E43: 45.136 | F43: 26.016 | G43: 0.215 | H43: A | I43: 45839 | J43: 高橋 | K43: GPa値をMPa列に入力した疑い
A44: TT-00043 | B44: 429.686 | D44: 342.33 | E44: 45.141 | F44: 25.571 | G44: 0.207 | H44: A | I44: 45840 | J44: 伊藤
A45: TT-00044 | B45: 603.711 | D45: 458.506 | E45: 38.439 | F45: 24.132 | G45: 0.185 | H45: C | I45: 45848 | J45: 渡辺
A46: TT-00045 | B46: 581.079 | D46: 454.504 | E46: 38.396 | F46: 24.072 | G46: 0.199 | H46: A | I46: 45849 | J46: 山田
A47: TT-00046 | B47: 541.926 | D47: 421.567 | E47: 41.996 | F47: 25.858 | G47: 0.206 | H47: A | I47: 45851 | J47: 佐藤
A48: TT-00047 | B48: 547.609 | D48: 427.044 | E48: 42.289 | F48: 26.62 | G48: 0.214 | H48: A | I48: 45852 | J48: 鈴木
A49: TT-00048 | B49: 327.838 | D49: 255.437 | E49: 48.8 | F49: 28.102 | G49: 0.243 | H49: A | I49: 45854 | J49: 高橋
A50: TT-00049 | B50: 328.476 | D50: 259.632 | E50: 48.372 | F50: 33.902 | G50: 0.216 | H50: A | I50: 45855 | J50: 伊藤
A51: TT-00050 | B51: 402.148 | D51: 315.46 | E51: 47.494 | F51: 29.56 | G51: 0.23 | H51: A | I51: 45857 | J51: 渡辺
A52: TT-00051 | B52: 396.198 | C52: 319.507 | E52: 46.887 | F52: 33.723 | G52: 0.207 | H52: A | I52: 45858 | J52: 山田
A53: TT-00052 | B53: 396.392 | C53: 315.324 | E53: 46.942 | F53: 29.078 | G53: 0.235 | H53: A | I53: 45859 | J53: 佐藤
A54: TT-00053 | B54: 512.528 | C54: 397.785 | E54: 43.14 | F54: 25.06 | G54: 0.205 | H54: A | I54: 45866 | J54: 鈴木
A55: TT-00054 | B55: 500.192 | C55: 383.823 | E55: 41.69 | F55: 28.732 | G55: 0.22 | H55: A | I55: 45867 | J55: 高橋
A56: TT-00055 | B56: 582.472 | C56: 452.193 | E56: 38.55 | F56: 21.45 | G56: 0.206 | H56: A | I56: 45875 | J56: 伊藤
A57: TT-00056 | B57: 583.114 | C57: 452.565 | E57: 39.121 | F57: 27.081 | G57: 0.184 | H57: A | I57: 45876 | J57: 渡辺
A58: TT-00057 | B58: 562.054 | C58: 438.788 | E58: 40.167 | F58: 24.483 | G58: 0.2 | H58: A | I58: 45875 | J58: 山田
A59: TT-00058 | B59: 558.403 | C59: 440.211 | E59: 39.017 | F59: 26.338 | G59: 0.198 | H59: A | I59: 45876 | J59: 佐藤
A60: TT-00059 | B60: 601.51 | C60: 462.061 | E60: 37.619 | F60: 23.834 | G60: 0.179 | H60: A | I60: 45878 | J60: 鈴木
...

Sheet 焼鈍板組織
A1: 焼鈍板組織_key** | B1: 画像リンク名 | C1: 倍率 | D1: 腐食 | E1: 観察位置 | F1: 断面方向 | G1: 画像状態 | H1: 撮影日 | I1: 撮影者 | J1: 備考
A2: AMS-00001 | B2: images/anneal/AN-00001_100x_ナイタール_板厚中央.png | C2: 100x | D2: ナイタール | E2: 板厚中央 | F2: L断面 | G2: 利用可 | H2: 45759 | I2: 山田
A3: AMS-00002 | B3: images/anneal/AN-00001_500x_ナイタール_板厚中央.png | C3: 500x | D3: ナイタール | E3: 板厚中央 | F3: L断面 | G3: 利用可 | H3: 45760 | I3: 佐藤
A4: AMS-00003 | B4: images/anneal/AN-00002_100x_ナイタール_板厚中央.png | C4: 100x | D4: ナイタール | E4: 板厚中央 | F4: L断面 | G4: 利用可 | H4: 45762 | I4: 鈴木
A5: AMS-00004 | B5: images/anneal/AN-00002_500x_ナイタール_板厚中央.png | C5: 500x | D5: ナイタール | E5: 板厚中央 | F5: L断面 | G5: 利用可 | H5: 45763 | I5: 高橋
A6: AMS-00005 | B6: images/anneal/AN-00003_100x_ナイタール_板厚中央.png | C6: 100x | D6: ナイタール | E6: 板厚中央 | F6: L断面 | G6: 利用可 | H6: 45765 | I6: 伊藤
A7: AMS-00006 | B7: images/anneal/AN-00003_500x_ナイタール_板厚中央.png | C7: 500x | D7: ナイタール | E7: 板厚中央 | F7: L断面 | G7: 利用可 | H7: 45766 | I7: 渡辺
A8: AMS-00007 | B8: images/anneal/AN-00003_1000x_レペラ_表層.png | C8: 1000x | D8: レペラ | E8: 表層 | F8: L断面 | G8: 利用可 | H8: 45767 | I8: 山田
A9: AMS-00008 | B9: images/anneal/AN-00003_1000x_ナイタール_1/4厚.png | C9: 1000x | D9: ナイタール | E9: 1/4厚 | F9: C断面 | G9: 利用可 | H9: 45768 | I9: 佐藤
A10: AMS-00009 | B10: images/anneal/AN-00009_100x_ナイタール_板厚中央.png | C10: 100x | D10: ナイタール | E10: 板厚中央 | F10: L断面 | G10: 利用可 | H10: 45786 | I10: 鈴木
A11: AMS-00010 | B11: images/anneal/AN-00009_500x_ナイタール_板厚中央.png | C11: 500x | D11: ナイタール | E11: 板厚中央 | F11: L断面 | G11: 利用可 | H11: 45787 | I11: 高橋
A12: AMS-00011 | B12: images/anneal/AN-00013_100x_ナイタール_板厚中央.png | C12: 100x | D12: ナイタール | E12: 板厚中央 | F12: L断面 | G12: 利用可 | H12: 45798 | I12: 伊藤
A13: AMS-00012 | B13: images/anneal/AN-00013_500x_ナイタール_板厚中央.png | C13: 500x | D13: ナイタール | E13: 板厚中央 | F13: L断面 | G13: 利用可 | H13: 45799 | I13: 渡辺
... A220: AMS-00219 | B220: images/anneal/AN-00192_1000x_レペラ_表層.png | C220: 1000x | D220: レペラ | E220: 表層 | F220: L断面 | G220: 利用可 | H220: 45768 | I220: 鈴木

Sheet 測定点マスタ
A1: 設備コード | B1: 点順 | C1: 測温点コード | D1: 名称 | E1: 工程 | F1: 入口からの距離[m] | G1: 出口までの残距離[m] | H1: 実機温度計 | I1: 利用温度
A2: AN-LINE-1 | B2: 1 | C2: P01 | D2: 開始 | E2: 開始 | F2: 0 | G2: 177 | I2: ◯
A3: AN-LINE-1 | B3: 2 | C3: P02 | D3: 予熱帯 | E3: PHF | F3: 15 | G3: 162 | H3: ◯
A4: AN-LINE-1 | B4: 3 | C4: P03 | D4: 直下帯 | E4: DFF | F4: 25 | G4: 152 | H4: ◯
A5: AN-LINE-1 | B5: 4 | C5: P04 | D5: 加熱帯 | E5: RTH | F5: 34 | G5: 143 | H5: ◯ | I5: ◯
A6: AN-LINE-1 | B6: 5 | C6: P05 | D6: 均熱帯 | E6: RTS | F6: 44 | G6: 133 | H6: ◯ | I6: ◯
A7: AN-LINE-1 | B7: 6 | C7: P06 | D7: 徐冷帯 | E7: 4BR入 | F7: 54 | G7: 123
A8: AN-LINE-1 | B8: 7 | C8: P07 | D8: 徐冷帯（温度計） | E8: SCS | F8: 60 | G8: 117 | H8: ◯ | I8: ◯
A9: AN-LINE-1 | B9: 8 | C9: P08 | D9: 1急冷帯入側 | E9: 1RCS入 | F9: 66 | G9: 111
A10: AN-LINE-1 | B10: 9 | C10: P09 | D10: 1急冷帯入側 | E10: 1RCS | F10: 73 | G10: 104 | H10: ◯ | I10: ◯
A11: AN-LINE-1 | B11: 10 | C11: P10 | D11: 2急冷帯 | E11: 2RCS | F11: 81 | G11: 96 | H11: ◯ | I11: ◯
A12: AN-LINE-1 | B12: 11 | C12: P11 | D12: 保持帯(温度計) | E12: HDS | F12: 88 | G12: 89 | H12: ◯ | I12: ◯
A13: AN-LINE-1 | B13: 12 | C13: P12 | D13: 3急冷入側 | E13: 3RCS入 | F13: 92 | G13: 85
A14: AN-LINE-1 | B14: 13 | C14: P13 | D14: 3急冷帯 | E14: 3RCS | F14: 97 | G14: 80 | H14: ◯ | I14: ◯
A15: AN-LINE-1 | B15: 14 | C15: P14 | D15: ダミー | E15: ダミー | F15: 102 | G15: 75
A16: AN-LINE-1 | B16: 15 | C16: P15 | D16: 1再加熱帯 | E16: 1RHF | F16: 104 | G16: 73 | H16: ◯ | I16: ◯
A17: AN-LINE-1 | B17: 16 | C17: P16 | D17: 過時効帯 | E17: OAS入側 | F17: 109 | G17: 68 | H17: ◯ | I17: ◯
A18: AN-LINE-1 | B18: 17 | C18: P17 | D18: 過時効帯 | E18: OAS入側中間 | F18: 115 | G18: 62 | H18: ◯ | I18: ◯
A19: AN-LINE-1 | B19: 18 | C19: P18 | D19: 過時効帯 | E19: OAS出口 | F19: 122 | G19: 55 | H19: ◯ | I19: ◯
A20: AN-LINE-1 | B20: 19 | C20: P19 | D20: 2再加熱帯 | E20: 2RHF | F20: 127 | G20: 50 | H20: ◯ | I20: ◯
A21: AN-LINE-1 | B21: 20 | C21: P20 | D21: 最終冷却帯 | E21: FCS | F21: 133 | G21: 44 | H21: ◯ | I21: ◯
A22: AN-LINE-1 | B22: 21 | C22: P21 | D22: めっき浴 | E22: GF入 | F22: 145 | G22: 32
A23: AN-LINE-1 | B23: 22 | C23: P22 | D23: 合金化炉 | E23: GF | F23: 146.78571 | G23: 30.214286 | H23: ◯ | I23: ◯
A24: AN-LINE-1 | B24: 23 | C24: P23 | D24: 合金化保持帯 | E24: GHF | F24: 152.82143 | G24: 24.178571 | H24: ◯ | I24: ◯
A25: AN-LINE-1 | B25: 24 | C25: P24 | D25: 高棟トップロール | E25: 高棟トップロール | F25: 158.85714 | G25: 18.142857 | H25: ◯
A26: AN-LINE-1 | B26: 25 | C26: P25 | D26: AJC | E26: AJC | F26: 164.89286 | G26: 12.107143 | H26: ◯ | I26: ◯
A27: AN-LINE-1 | B27: 26 | C27: P26 | D27: 水冷入 | E27: 水冷入 | F27: 170.92857 | G27: 6.0714286
A28: AN-LINE-1 | B28: 27 | C28: P27 | D28: 水冷 | E28: 水冷 | F28: 176.96429 | G28: 0.035714286 | I28: ◯
